
<robot name="bottle">
  <link name="bottle_link">
    <visual>
      <geometry>
        <cylinder length="0.2" radius="0.04"/>
      </geometry>
    </visual>
    <collision>
      <geometry>
        <cylinder length="0.2" radius="0.04"/>
      </geometry>
    </collision>
    <inertial>
      <mass value="0.1"/>
      <inertia ixx="0.001" iyy="0.001" izz="0.001" ixy="0" ixz="0" iyz="0"/>
    </inertial>
  </link>

  <link name="cap_link">
    <visual>
      <geometry>
        <cylinder length="0.02" radius="0.03"/>
      </geometry>
      <origin xyz="0 0 0.11" rpy="0 0 0"/> </visual>
    </link>

  <joint name="cap_joint" type="revolute">
    <parent link="bottle_link"/>
    <child link="cap_link"/>
    <origin xyz="0 0 0.1" rpy="0 0 0"/> <axis xyz="0 0 1"/> <limit lower="-6.28" upper="6.28" effort="10" velocity="1.0"/>
    <dynamics damping="0.1" friction="0.8"/> </joint>
</robot>