<mujoco model="nuri_4s">
  <compiler angle="radian"/>

  <asset>
    <mesh name="Nuri4s_0" file="Nuri4s_0.stl"/>
    <mesh name="Nuri4s_1" file="Nuri4s_1.stl"/>
    <mesh name="Nuri4s_2" file="Nuri4s_2.stl"/>
    <mesh name="Nuri4s_3" file="Nuri4s_3.stl"/>
    <mesh name="Nuri4s_4" file="Nuri4s_4.stl"/>
    <mesh name="Nuri4s_5" file="Nuri4s_5.stl"/>
    <mesh name="Nuri4s_6" file="Nuri4s_6.stl"/>
  </asset>

  <worldbody>
    <body name="nuri_4s_link0" pos="0 0 0" quat="1 0 0 0">
      <inertial pos="-0.0047088 0.0013609 0.0700112" mass="3.795" fullinertia="0.0245374 0.0298651 0.0304886 -0.0000807 0.0008462 -0.0001636"/>
      <geom name="nuri_4s_link0_visual" type="mesh" rgba="1 1 1 1" mesh="Nuri4s_0"/>
      <geom type="capsule" fromto="0 0 0 0.2 0 0" size="0.01" rgba="1 0 0 1" contype="0" conaffinity="0"/>
      <geom type="capsule" fromto="0 0 0 0 0.2 0" size="0.01" rgba="0 1 0 1" contype="0" conaffinity="0"/>
      <geom type="capsule" fromto="0 0 0 0 0 0.2" size="0.01" rgba="0 0 1 1" contype="0" conaffinity="0"/>
      <body name="nuri_4s_link1" pos="0 0 0.09" quat="1 0 0 0" >
        <inertial pos="3e-07 -0.007652 0.168027" mass="3.399" fullinertia="0.0341486 0.0337188 0.0065689 -0.0024189 -0.0000048 -0.000001"/>
        <joint name="nuri_4s_joint0" pos="0 0 0" axis="0 0 1" range="-6.28319 6.28319" actuatorfrcrange="-431.97 431.97" damping="0.1" frictionloss="10"/>
        <geom name="nuri_4s_link1_visual" type="mesh" rgba="1 1 1 1" mesh="Nuri4s_1"/>
        <geom type="capsule" fromto="0 0 0 0.2 0 0" size="0.01" rgba="1 0 0 1" contype="0" conaffinity="0"/>
        <geom type="capsule" fromto="0 0 0 0 0.2 0" size="0.01" rgba="0 1 0 1" contype="0" conaffinity="0"/>
        <geom type="capsule" fromto="0 0 0 0 0 0.2" size="0.01" rgba="0 0 1 1" contype="0" conaffinity="0"/>
        <body name="nuri_4s_link2" pos="0 -0.04 0.238" quat="0.707107 -0.707107 0 0">
          <inertial pos="0.0166661 -0.211671 -0.0293009" mass="4.291" fullinertia="0.14042515 0.0126477499989528 0.140401980001047 -0.01494819200008 0.000390087996934075 0.00255276697379717"/>
          <joint name="nuri_4s_joint1" pos="0 0 0" axis="0 0 1" range="-2.70526 2.44346" actuatorfrcrange="-431.97 431.97" damping="0.1" frictionloss="10"/>
          <geom name="nuri_4s_link2_visual" type="mesh" rgba="1 1 1 1" mesh="Nuri4s_2"/>
          <geom type="capsule" fromto="0 0 0 0.2 0 0" size="0.01" rgba="1 0 0 1" contype="0" conaffinity="0"/>
          <geom type="capsule" fromto="0 0 0 0 0.2 0" size="0.01" rgba="0 1 0 1" contype="0" conaffinity="0"/>
          <geom type="capsule" fromto="0 0 0 0 0 0.2" size="0.01" rgba="0 0 1 1" contype="0" conaffinity="0"/>
          <body name="nuri_4s_link3" pos="0.05 -0.4 0" quat="1 0 0 0">
            <inertial pos="-0.0249002 -0.110739 0.030014" mass="2.018" fullinertia="0.02103842 0.00429357999930064 0.0216766700006994 -0.00402664699990075 -0.000483905000825879 0.00170489899643467"/>
            <joint name="nuri_4s_joint2" pos="0 0 0" axis="0 0 1" range="-3.05433 2.35619" actuatorfrcrange="-197.23 197.23" damping="0.1" frictionloss="10"/>
            <geom name="nuri_4s_link3_visual" type="mesh" rgba="1 1 1 1" mesh="Nuri4s_3"/>
            <geom type="capsule" fromto="0 0 0 0.2 0 0" size="0.01" rgba="1 0 0 1" contype="0" conaffinity="0"/>
            <geom type="capsule" fromto="0 0 0 0 0.2 0" size="0.01" rgba="0 1 0 1" contype="0" conaffinity="0"/>
            <geom type="capsule" fromto="0 0 0 0 0 0.2" size="0.01" rgba="0 0 1 1" contype="0" conaffinity="0"/>
            <body name="nuri_4s_link4" pos="-0.05 -0.195 0.04" quat="0.707107 0.707107 0 0">
              <inertial pos="2.54e-05 0.0107528 0.160977" mass="1.882" fullinertia="0.01331985 0.01251989 0.00278828 -0.00000185 0.000000867 -0.00143894"/>
              <joint name="nuri_4s_joint3" pos="0 0 0" axis="0 0 1" range="-6.28319 6.28319" actuatorfrcrange="-79.79 79.79" damping="0.1" frictionloss="10"/>
              <geom name="nuri_4s_link4_visual" type="mesh" rgba="1 1 1 1" mesh="Nuri4s_4"/>
              <geom type="capsule" fromto="0 0 0 0.2 0 0" size="0.01" rgba="1 0 0 1" contype="0" conaffinity="0"/>
              <geom type="capsule" fromto="0 0 0 0 0.2 0" size="0.01" rgba="0 1 0 1" contype="0" conaffinity="0"/>
              <geom type="capsule" fromto="0 0 0 0 0 0.2" size="0.01" rgba="0 0 1 1" contype="0" conaffinity="0"/>
              <body name="nuri_4s_link5" pos="0 0.07 0.205042" quat="0.707107 -0.707107 0 0">
                <inertial pos="-2.9e-06 -0.0339762 0.0368269" mass="1.507" fullinertia="0.00503263 0.00394479999986396 0.00261442000013604 0.000001293000001246 -0.0000060749999997348 0.000331648000272865"/>
                <joint name="nuri_4s_joint4" pos="0 0 0" axis="0 0 1" range="-6.28319 6.28319" actuatorfrcrange="-79.79 79.79" damping="0.1" frictionloss="10"/>
                <geom name="nuri_4s_link5_visual" type="mesh" rgba="1 1 1 1" mesh="Nuri4s_5"/>
                <geom type="capsule" fromto="0 0 0 0.2 0 0" size="0.01" rgba="1 0 0 1" contype="0" conaffinity="0"/>
                <geom type="capsule" fromto="0 0 0 0 0.2 0" size="0.01" rgba="0 1 0 1" contype="0" conaffinity="0"/>
                <geom type="capsule" fromto="0 0 0 0 0 0.2" size="0.01" rgba="0 0 1 1" contype="0" conaffinity="0"/>
                <body name="nuri_4s_link6" pos="0 -0.075 0.066" quat="0.707107 0.707107 0 0">
                  <inertial pos="-7.26e-05 -7.90001e-05 0.0106047" mass="0.634" fullinertia="0.00099702 0.00100253 0.00044795 -0.000001376 0.000000897 0.000001581"/>  
                  <joint name="nuri_4s_joint5" pos="0 0 0" axis="0 0 1" range="-6.28319 6.28319" actuatorfrcrange="-79.79 79.79" damping="0.1" frictionloss="10"/>
                  <geom name="nuri_4s_link6_visual" type="mesh" rgba="1 1 1 1" mesh="Nuri4s_6"/>
                  <geom type="capsule" fromto="0 0 0 0.2 0 0" size="0.01" rgba="1 0 0 1" contype="0" conaffinity="0"/>
                  <geom type="capsule" fromto="0 0 0 0 0.2 0" size="0.01" rgba="0 1 0 1" contype="0" conaffinity="0"/>
                  <geom type="capsule" fromto="0 0 0 0 0 0.2" size="0.01" rgba="0 0 1 1" contype="0" conaffinity="0"/>
                  <site name="end_effector" pos="0 0 0.05" size="0.01" rgba="1 0 0 1"/>
                </body>
              </body>
            </body>
          </body>
        </body>
      </body>
    </body>
  </worldbody>

  <actuator>
    <motor name="nuri_4s_motor0" joint="nuri_4s_joint0"/>
    <motor name="nuri_4s_motor1" joint="nuri_4s_joint1"/>
    <motor name="nuri_4s_motor2" joint="nuri_4s_joint2"/>
    <motor name="nuri_4s_motor3" joint="nuri_4s_joint3"/>
    <motor name="nuri_4s_motor4" joint="nuri_4s_joint4"/>
    <motor name="nuri_4s_motor5" joint="nuri_4s_joint5"/>
  </actuator>

  <!-- <sensor>
    <jointactuator name="nuri_4s_JFT0" joint="nuri_4s_joint0"/>
    <jointactuator name="nuri_4s_JFT1" joint="nuri_4s_joint1"/>
    <jointactuator name="nuri_4s_JFT2" joint="nuri_4s_joint2"/>
    <jointactuator name="nuri_4s_JFT3" joint="nuri_4s_joint3"/>
    <jointactuator name="nuri_4s_JFT4" joint="nuri_4s_joint4"/>
    <jointactuator name="nuri_4s_JFT5" joint="nuri_4s_joint5"/>
  </sensor> -->
</mujoco>