<?xml version="1.0" ?>
<!-- =================================================================================== -->
<!-- |    This document was autogenerated by xacro from nuri_4s_arm_hand.urdf.xacro      | -->
<!-- |    EDITING THIS FILE BY HAND IS NOT RECOMMENDED                                 | -->
<!-- =================================================================================== -->
<robot name="nuri_4s">
    <link name="world"/>
    <link name="nuri_4s_link0">
        <visual name="nuri_4s_link0_visual">
            <origin rpy="0 0 0" xyz="0 0 0"/>
            <geometry>
                <mesh filename="Nuri4s_0.stl"/>
            </geometry>
            <material name="nuri_4s_white"/>
        </visual>
        <collision name="nuri_4s_link0_collision">
            <origin rpy="0 0 0" xyz="0 0 0"/>
            <geometry>
                <mesh filename="../meshes/collision/Nuri4s_0.stl"/>
            </geometry>
        </collision>
        <inertial>
            <origin xyz="-0.0047088 0.0013609 0.0700112" rpy="0 0 0"/>
            <mass value="3.795"/>
            <inertia ixx="0.0245374" ixy="-0.0000807" ixz="0.0008462" iyy="0.0298651" iyz="-0.0001636" izz="0.0304886"/>
        </inertial>
    </link>
    <link name="nuri_4s_link1">
        <visual name="nuri_4s_link1_visual">
            <origin rpy="0 0 0" xyz="0 0 0"/>
            <geometry>
                <mesh filename="Nuri4s_1.stl"/>
            </geometry>
            <material name="nuri_4s_white"/>
        </visual>
        <collision name="nuri_4s_link1_collision">
            <origin rpy="0 0 0" xyz="0 0 0"/>
            <geometry>
                <mesh filename="../meshes/collision/Nuri4s_1.stl"/>
            </geometry>
        </collision>
        <inertial>
            <origin xyz="0.0000003 -0.007652 0.1680273" rpy="0 0 0"/>
            <mass value="3.399"/>
            <inertia ixx="0.0341486" ixy="-0.0024189" ixz="-0.0000048" iyy="0.0337188" iyz="-0.000001" izz="0.0065689"/>
        </inertial>
    </link>
    <link name="nuri_4s_link2">
        <visual name="nuri_4s_link2_visual">
            <origin rpy="0 0 0" xyz="0 0 0"/>
            <geometry>
                <mesh filename="Nuri4s_2.stl"/>
            </geometry>
            <material name="nuri_4s_white"/>
        </visual>
        <collision name="nuri_4s_link2_collision">
            <origin rpy="0 0 0" xyz="0 0 0"/>
            <geometry>
                <mesh filename="../meshes/collision/Nuri4s_2.stl"/>
            </geometry>
        </collision>
        <inertial>
            <origin xyz="0.0166661 -0.21167129999399 -0.0293009000434145" rpy="0 0 0"/>
            <mass value="4.291"/>
            <inertia ixx="0.14042515" ixy="-0.01494819200008" ixz="0.000390087996934075" iyy="0.0126477499989528" iyz="0.00255276697379717" izz="0.140401980001047"/>
        </inertial>
    </link>
    <link name="nuri_4s_link3">
        <visual name="nuri_4s_link3_visual">
            <origin rpy="0 0 0" xyz="0 0 0"/>
            <geometry>
                <mesh filename="Nuri4s_3.stl"/>
            </geometry>
            <material name="nuri_4s_white"/>
        </visual>
        <collision name="nuri_4s_link3_collision">
            <origin rpy="0 0 0" xyz="0 0 0"/>
            <geometry>
                <mesh filename="../meshes/collision/Nuri4s_3.stl"/>
            </geometry>
        </collision>
        <inertial>
            <origin xyz="-0.0249002 -0.110739200006156 0.0300139998952456" rpy="0 0 0"/>
            <mass value="2.018"/>
            <inertia ixx="0.02103842" ixy="-0.00402664699990075" ixz="-0.000483905000825879" iyy="0.00429357999930064" iyz="0.00170489899643467" izz="0.0216766700006994"/>
        </inertial>
    </link>
    <link name="nuri_4s_link4">
        <visual name="nuri_4s_link4_visual">
            <origin rpy="0 0 0" xyz="0 0 0"/>
            <geometry>
                <mesh filename="Nuri4s_4.stl"/>
            </geometry>
            <material name="nuri_4s_white"/>
        </visual>
        <collision name="nuri_4s_link4_collision">
            <origin rpy="0 0 0" xyz="0 0 0"/>
            <geometry>
                <mesh filename="../meshes/collision/Nuri4s_4.stl"/>
            </geometry>
        </collision>
        <inertial>
            <origin xyz="0.0000254 0.0107527998779635 0.160977100008204" rpy="0 0 0"/>
            <mass value="1.882"/>
            <inertia ixx="0.01331985" ixy="-0.00000185" ixz="0.000000867" iyy="0.01251989" iyz="-0.00143894" izz="0.00278828"/>
        </inertial>
    </link>
    <link name="nuri_4s_link5">
        <visual name="nuri_4s_link5_visual">
            <origin rpy="0 0 0" xyz="0 0 0"/>
            <geometry>
                <mesh filename="Nuri4s_5.stl"/>
            </geometry>
            <material name="nuri_4s_white"/>
        </visual>
        <collision name="nuri_4s_link5_collision">
            <origin rpy="0 0 0" xyz="0 0 0"/>
            <geometry>
                <mesh filename="../meshes/collision/Nuri4s_5.stl"/>
            </geometry>
        </collision>
        <inertial>
            <origin xyz="-0.0000029 -0.0339762000157573 0.0368268998709948" rpy="0 0 0"/>
            <mass value="1.507"/>
            <inertia ixx="0.00503263" ixy="0.000001293000001246" ixz="-0.0000060749999997348" iyy="0.00394479999986396" iyz="0.000331648000272865" izz="0.00261442000013604"/>
        </inertial>
    </link>
    <link name="nuri_4s_link6">
        <visual name="nuri_4s_link6_visual">
            <origin rpy="0 0 0" xyz="0 0 0"/>
            <geometry>
                <mesh filename="Nuri4s_6.stl"/>
            </geometry>
            <material name="nuri_4s_white"/>
        </visual>
        <collision name="nuri_4s_link6_collision">
            <origin rpy="0 0 0" xyz="0 0 0"/>
            <geometry>
                <mesh filename="../meshes/collision/Nuri4s_6.stl"/>
            </geometry>
        </collision>
        <inertial>
            <origin xyz="-0.0000726 -0.0000790001374193217 0.0106047000217409" rpy="0 0 0"/>
            <mass value="0.634"/>
            <inertia ixx="0.00099702" ixy="-0.000001376" ixz="0.000000897" iyy="0.00100253" iyz="0.000001581" izz="0.00044795"/>
        </inertial>
    </link>
    <link name="tcp"/>    

    <joint name="global" type="fixed">
        <origin rpy="0 0 0" xyz="0 0 0"/>
        <parent link="world"/>
        <child link="nuri_4s_link0"/>
    </joint>
    <joint name="nuri_4s_joint0" type="revolute">
        <origin rpy="0 0 0" xyz="0 0 0.09"/>
        <parent link="nuri_4s_link0"/>
        <child link="nuri_4s_link1"/>
        <axis xyz="0 0 1"/>
        <dynamics damping="0.1" friction="10.0"/>
        <limit effort="431.97" lower="-6.283185307179586" upper="6.283185307179586" velocity="3.141592653589793"/>
    </joint>
    <joint name="nuri_4s_joint1" type="revolute">
        <parent link="nuri_4s_link1"/>
        <child link="nuri_4s_link2"/>
        <origin rpy="-1.570796327 0.0 0.0" xyz="0.0 -0.04 0.238"/>
        <axis xyz="0 0 1"/>
        <dynamics damping="0.1" friction="10.0"/>
        <limit effort="431.97" lower="-2.705260340591211" upper="2.443460952792061" velocity="3.141592653589793"/>
    </joint>
    <joint name="nuri_4s_joint2" type="revolute">
        <parent link="nuri_4s_link2"/>
        <child link="nuri_4s_link3"/>
        <origin rpy="0.0 0.0 0.0" xyz="0.05 -0.4 0.0"/>
        <axis xyz="0 0 1"/>
        <dynamics damping="0.1" friction="10.0"/>
        <limit effort="197.23" lower="-3.0543261909900767" upper="2.356194490192345" velocity="3.141592653589793"/>
    </joint>
    <joint name="nuri_4s_joint3" type="revolute">
        <parent link="nuri_4s_link3"/>
        <child link="nuri_4s_link4"/>
        <origin rpy="1.570796327 0.0 0.0" xyz="-0.05 -0.195 0.04"/>
        <axis xyz="0 0 1"/>
        <dynamics damping="0.1" friction="10.0"/>
        <limit effort="79.79" lower="-6.283185307179586" upper="6.283185307179586" velocity="3.141592653589793"/>
    </joint>
    <joint name="nuri_4s_joint4" type="revolute">
        <parent link="nuri_4s_link4"/>
        <child link="nuri_4s_link5"/>
        <origin rpy="-1.570796327 0.0 0.0" xyz="0.0 0.07 0.2050424"/>
        <axis xyz="0 0 1"/>
        <dynamics damping="0.1" friction="10.0"/>
        <limit effort="79.79" lower="-6.283185307179586" upper="6.283185307179586" velocity="3.141592653589793"/>
    </joint>
    <joint name="nuri_4s_joint5" type="revolute">
        <parent link="nuri_4s_link5"/>
        <child link="nuri_4s_link6"/>
        <origin rpy="1.570796327 0.0 0.0" xyz="0.0 -0.075 0.066"/>
        <axis xyz="0 0 1"/>
        <dynamics damping="0.1" friction="10.0"/>
        <limit effort="79.79" lower="-6.283185307179586" upper="6.283185307179586" velocity="3.141592653589793"/>
    </joint>
    <joint name="tcp_joint" type="fixed">
        <parent link="nuri_4s_link6"/>
        <child link="tcp"/>
        <origin rpy="0.0 0.0 0.0" xyz="0.0 0.0 0.0285"/>
    </joint>

    <material name="nuri_4s_white">
        <color rgba="1. 1. 1. 1."/>
    </material>
</robot>